<?xml version="1.0" ?>
<!-- =================================================================================== -->
<!-- |    This document was autogenerated by xacro from W:\Homework\robotics\new_description\urdf\new.xacro | -->
<!-- |    EDITING THIS FILE BY HAND IS NOT RECOMMENDED                                 | -->
<!-- =================================================================================== -->
<robot xmlns:xacro="http://www.ros.org/wiki/xacro" name="new">
  <material name="silver">
    <color rgba="0.700 0.700 0.700 1.000"/>
  </material>
  <transmission name="Revolute 1_tran">
    <type>transmission_interface/SimpleTransmission</type>
    <joint name="Revolute 1">
      <hardwareInterface>hardware_interface/EffortJointInterface</hardwareInterface>
    </joint>
    <actuator name="Revolute 1_actr">
      <hardwareInterface>hardware_interface/EffortJointInterface</hardwareInterface>
      <mechanicalReduction>1</mechanicalReduction>
    </actuator>
  </transmission>
  <transmission name="Revolute 2_tran">
    <type>transmission_interface/SimpleTransmission</type>
    <joint name="Revolute 2">
      <hardwareInterface>hardware_interface/EffortJointInterface</hardwareInterface>
    </joint>
    <actuator name="Revolute 2_actr">
      <hardwareInterface>hardware_interface/EffortJointInterface</hardwareInterface>
      <mechanicalReduction>1</mechanicalReduction>
    </actuator>
  </transmission>
  <transmission name="Revolute 3_tran">
    <type>transmission_interface/SimpleTransmission</type>
    <joint name="Revolute 3">
      <hardwareInterface>hardware_interface/EffortJointInterface</hardwareInterface>
    </joint>
    <actuator name="Revolute 3_actr">
      <hardwareInterface>hardware_interface/EffortJointInterface</hardwareInterface>
      <mechanicalReduction>1</mechanicalReduction>
    </actuator>
  </transmission>
  <transmission name="Revolute 4_tran">
    <type>transmission_interface/SimpleTransmission</type>
    <joint name="Revolute 4">
      <hardwareInterface>hardware_interface/EffortJointInterface</hardwareInterface>
    </joint>
    <actuator name="Revolute 4_actr">
      <hardwareInterface>hardware_interface/EffortJointInterface</hardwareInterface>
      <mechanicalReduction>1</mechanicalReduction>
    </actuator>
  </transmission>
  <gazebo>
    <plugin name="control" filename="libgazebo_ros_control.so"/>
  </gazebo>
  <gazebo reference="base_link">
    <material>Gazebo/Silver</material>
    <mu1>0.2</mu1>
    <mu2>0.2</mu2>
    <selfCollide>true</selfCollide>
    <gravity>true</gravity>
  </gazebo>
  <gazebo reference="front_right_1">
    <material>Gazebo/Silver</material>
    <mu1>0.2</mu1>
    <mu2>0.2</mu2>
    <selfCollide>true</selfCollide>
  </gazebo>
  <gazebo reference="rear_right_1">
    <material>Gazebo/Silver</material>
    <mu1>0.2</mu1>
    <mu2>0.2</mu2>
    <selfCollide>true</selfCollide>
  </gazebo>
  <gazebo reference="rear_left_1">
    <material>Gazebo/Silver</material>
    <mu1>0.2</mu1>
    <mu2>0.2</mu2>
    <selfCollide>true</selfCollide>
  </gazebo>
  <gazebo reference="front_left_1">
    <material>Gazebo/Silver</material>
    <mu1>0.2</mu1>
    <mu2>0.2</mu2>
    <selfCollide>true</selfCollide>
  </gazebo>
  <link name="base_link">
    <inertial>
      <origin xyz="7.520858146252514e-12 -0.005127814038988313 0.04367176151374712" rpy="0 0 0"/>
      <mass value="40.195619262816834"/>
      <inertia ixx="0.276138" iyy="0.185347" izz="0.405195" ixy="0.0" iyz="-0.007834" ixz="0.0"/>
    </inertial>
    <visual>
      <origin xyz="0 0 0" rpy="0 0 0"/>
      <geometry>
        <mesh filename="package://new_description/meshes/base_link.stl" scale="0.001 0.001 0.001"/>
      </geometry>
      <material name="silver"/>
    </visual>
    <collision>
      <origin xyz="0 0 0" rpy="0 0 0"/>
      <geometry>
        <mesh filename="package://new_description/meshes/base_link.stl" scale="0.001 0.001 0.001"/>
      </geometry>
    </collision>
  </link>
  <link name="front_right_1">
    <inertial>
      <origin xyz="-0.015 -2.7755575615628914e-17 -6.938893903907228e-18" rpy="0 0 0"/>
      <mass value="0.1766957372085043"/>
      <inertia ixx="0.000141" iyy="8.4e-05" izz="8.4e-05" ixy="0.0" iyz="-0.0" ixz="-0.0"/>
    </inertial>
    <visual>
      <origin xyz="0.1165 0.1825 -0.025" rpy="0 0 0"/>
      <geometry>
        <mesh filename="package://new_description/meshes/front_right_1.stl" scale="0.001 0.001 0.001"/>
      </geometry>
      <material name="silver"/>
    </visual>
    <collision>
      <origin xyz="0.1165 0.1825 -0.025" rpy="0 0 0"/>
      <geometry>
        <mesh filename="package://new_description/meshes/front_right_1.stl" scale="0.001 0.001 0.001"/>
      </geometry>
    </collision>
  </link>
  <link name="rear_right_1">
    <inertial>
      <origin xyz="-0.015 2.7755575615628914e-17 -6.938893903907228e-18" rpy="0 0 0"/>
      <mass value="0.1766957372085043"/>
      <inertia ixx="0.000141" iyy="8.4e-05" izz="8.4e-05" ixy="0.0" iyz="0.0" ixz="-0.0"/>
    </inertial>
    <visual>
      <origin xyz="0.1165 -0.1105 -0.025" rpy="0 0 0"/>
      <geometry>
        <mesh filename="package://new_description/meshes/rear_right_1.stl" scale="0.001 0.001 0.001"/>
      </geometry>
      <material name="silver"/>
    </visual>
    <collision>
      <origin xyz="0.1165 -0.1105 -0.025" rpy="0 0 0"/>
      <geometry>
        <mesh filename="package://new_description/meshes/rear_right_1.stl" scale="0.001 0.001 0.001"/>
      </geometry>
    </collision>
  </link>
  <link name="rear_left_1">
    <inertial>
      <origin xyz="0.015 0.0 0.0" rpy="0 0 0"/>
      <mass value="0.1766957372085043"/>
      <inertia ixx="0.000141" iyy="8.4e-05" izz="8.4e-05" ixy="0.0" iyz="0.0" ixz="0.0"/>
    </inertial>
    <visual>
      <origin xyz="-0.1165 -0.1105 -0.025" rpy="0 0 0"/>
      <geometry>
        <mesh filename="package://new_description/meshes/rear_left_1.stl" scale="0.001 0.001 0.001"/>
      </geometry>
      <material name="silver"/>
    </visual>
    <collision>
      <origin xyz="-0.1165 -0.1105 -0.025" rpy="0 0 0"/>
      <geometry>
        <mesh filename="package://new_description/meshes/rear_left_1.stl" scale="0.001 0.001 0.001"/>
      </geometry>
    </collision>
  </link>
  <link name="front_left_1">
    <inertial>
      <origin xyz="0.015 0.0 0.0" rpy="0 0 0"/>
      <mass value="0.1766957372085043"/>
      <inertia ixx="0.000141" iyy="8.4e-05" izz="8.4e-05" ixy="0.0" iyz="0.0" ixz="0.0"/>
    </inertial>
    <visual>
      <origin xyz="-0.1165 0.1825 -0.025" rpy="0 0 0"/>
      <geometry>
        <mesh filename="package://new_description/meshes/front_left_1.stl" scale="0.001 0.001 0.001"/>
      </geometry>
      <material name="silver"/>
    </visual>
    <collision>
      <origin xyz="-0.1165 0.1825 -0.025" rpy="0 0 0"/>
      <geometry>
        <mesh filename="package://new_description/meshes/front_left_1.stl" scale="0.001 0.001 0.001"/>
      </geometry>
    </collision>
  </link>
  <joint name="Revolute 1" type="continuous">
    <origin xyz="-0.1165 -0.1825 0.025" rpy="0 0 0"/>
    <parent link="base_link"/>
    <child link="front_right_1"/>
    <axis xyz="1.0 0.0 0.0"/>
  </joint>
  <joint name="Revolute 2" type="continuous">
    <origin xyz="-0.1165 0.1105 0.025" rpy="0 0 0"/>
    <parent link="base_link"/>
    <child link="rear_right_1"/>
    <axis xyz="1.0 0.0 0.0"/>
  </joint>
  <joint name="Revolute 3" type="continuous">
    <origin xyz="0.1165 0.1105 0.025" rpy="0 0 0"/>
    <parent link="base_link"/>
    <child link="rear_left_1"/>
    <axis xyz="1.0 0.0 0.0"/>
  </joint>
  <joint name="Revolute 4" type="continuous">
    <origin xyz="0.1165 -0.1825 0.025" rpy="0 0 0"/>
    <parent link="base_link"/>
    <child link="front_left_1"/>
    <axis xyz="1.0 0.0 0.0"/>
  </joint>
</robot>
